Workbook
Name Slicer_Condition: #N/A
Name Slicer_Gender: #N/A
Name Slicer_Hospital_Name: #N/A

Sheet Raw_Data (Original Dataset)
A1: Patient_ID | B1: Age | C1: Gender | D1: Condition | E1: Hospital | F1: Admission_Date | G1: Length_of_Stay | H1: Drug_Cost_GBP | I1: Outcome
A2: P0379 | D2: Kidney Disease | E2: Stafford Hospital | H2: 1715.89 | I2: Referred
A3: P0323 | D3: Diabetes | E3: stoke hospital | I3: Ongoing
A4: P1064 | B4: 94 | C4: Female | D4: Asthma | E4: New Cross Hospital | H4: 903.44 | I4: Recovered
A5: P0471 | D5: Asthma | E5: Stoke Hospital | G5: 18 | I5: Recovered
A6: P0002 | C6: Female | D6: Stroke | E6: Stoke Hospital | F6: 45497 | G6: 13 | I6: Deceased
A7: P0638 | C7: male | D7: Diabetes | E7: Russells Hall Hospital | F7: 45506 | H7: 568.76 | I7: Recovered
A8: P0364 | D8: Stroke | E8: New Cross Hospital | F8: 45360 | G8: 4 | I8: Ongoing
A9: P0553 | B9: 67 | D9: Asthma | E9: Stoke Hospital | F9: 45506 | H9: 1980.5 | I9: Deceased
A10: P0020 | B10: 91 | D10: COPD | E10: Walsall Manor | F10: 45600 | G10: 2 | I10: Recovered
A11: P0929 | C11: Female | D11: Kidney Disease | E11: Stafford Hospital | F11: 45338 | G11: 8 | I11: Ongoing
A12: P0325 | D12: Stroke | E12: Russells Hall Hospital | F12: 45613 | H12: 529.02
A13: P0489 | B13: 71 | C13: FEMALE | D13: Asthma | E13: Russells Hall Hospital | F13: 45332 | G13: 4
A14: P0468 | C14: FEMALE | E14: stoke hospital | F14: 45543 | H14: 1955.27 | I14: Ongoing
A15: P0361 | C15: male | D15: COPD | E15: Stafford Hospital | H15: 528.17 | I15: Ongoing
A16: P0072 | C16: Male | D16: Kidney Disease | E16: New Cross Hospital | F16: 45522 | I16: Recovered
A17: P0654 | C17: Female | D17: diabetes | E17: stoke hospital | F17: 45302 | I17: Referred
A18: P0855 | C18: Male | D18: Kidney Disease | E18: Stoke Hospital | F18: 45314 | G18: 12 | H18: 1382.89 | I18: Deceased
A19: P0237 | B19: 92 | C19: male | D19: Heart Disease | E19: New Cross Hospital | F19: 45486 | G19: 20
A20: P0062 | C20: male | D20: diabetes | E20: New Cross Hospital | G20: 18 | I20: Recovered
A21: P0415 | D21: Hypertension | E21: New Cross Hospital | F21: 45546 | I21: Deceased
A22: P0883 | C22: Female | D22: Stroke | E22: Russells Hall Hospital | F22: 45547 | I22: Referred
A23: P0132 | B23: 35 | C23: male | D23: Hypertension | E23: stoke hospital | F23: 45399 | H23: 1680.71 | I23: Referred
A24: P0927 | C24: male | D24: diabetes | E24: Stoke Hospital | F24: 45401
A25: P0040 | C25: Female | D25: Heart Disease | E25: New Cross Hospital | I25: Referred
A26: P0756 | B26: 36 | C26: Male | D26: Stroke | E26: Keele Hospital | F26: 45413 | I26: Referred
A27: P0558 | C27: male | E27: Stafford Hospital | F27: 45383 | H27: 110.9 | I27: Ongoing
A28: P0014 | C28: FEMALE | E28: New Cross Hospital | F28: 45336 | G28: 13 | H28: 922.99 | I28: Ongoing
A29: P1100 | B29: 33 | C29: male | D29: Asthma | E29: Stoke Hospital | F29: 45342 | I29: Recovered
A30: P0059 | C30: Female | D30: diabetes | E30: Russells Hall Hospital | F30: 45311 | I30: Ongoing
A31: P1062 | C31: FEMALE | D31: Kidney Disease | E31: stoke hospital | F31: 45564 | I31: Deceased
A32: P1147 | C32: male | D32: Asthma | E32: Russells Hall Hospital | F32: 45561
A33: P0412 | B33: 56 | C33: FEMALE | E33: stoke hospital | F33: 45398
A34: P1153 | C34: Male | D34: Kidney Disease | E34: stoke hospital | F34: 45485 | I34: Recovered
A35: P0261 | C35: male | D35: Heart Disease | E35: New Cross Hospital | F35: 45567 | I35: Recovered
A36: P0073 | C36: Female | D36: Hypertension | E36: Keele Hospital | H36: 293.74 | I36: Referred
A37: P1193 | B37: 63 | C37: Male | E37: Walsall Manor | F37: 45456
A38: P0419 | D38: Stroke | E38: Keele Hospital | F38: 45515
A39: P0399 | B39: 35 | C39: Female | D39: Stroke | E39: stoke hospital | G39: 12 | I39: Ongoing
A40: P1113 | C40: Female | D40: Stroke | E40: Russells Hall Hospital | F40: 45359 | G40: 13 | I40: Recovered
...

Sheet Cleaned_Data
A1: Patient_ID | B1: Age (Years) | C1: Gender | D1: Condition | E1: Hospital Name | F1: Admission_Date | G1: Length_of_Stay (Days) | H1: Drug_Cost_GBP | I1: Outcome | J1: Age Group | K1: High Cost Case | L1: Age > 75 | M1: > AverageCost | N1: Admission Month
A2: P1189 | B2: 95 | C2: FEMALE | D2: Diabetes | E2: Stafford Hospital | F2: 45629 | G2: 7 | H2: 1542.11 | I2: Referred | J2: {=_xlfn.IFS(Table3[[#This Row],[Age (Years)]] < 40, "Young", Table3[[#This Row],[Age (Years)]] >= 40, "Middle", Table3[[#This Row],[Age (Years)]] > 60, "Senior")} -> Middle | K2: {=_xlfn.IFS(Table3[[#This Row],[Drug_Cost_GBP]] > 1200, "High Cost", Table3[[#This Row],[Drug_Cost_GBP]] < 1200, "Normal")} -> High Cost | L2: {=IFERROR(_xlfn.IFS(Table3[[#This Row],[Age (Years)]] > 75, "YES", Table3[[#This Row],[Age (Years)]] < 75, "NO"), "UNKNOWN")} -> YES | M2: =IF(Table3[[#This Row],[Drug_Cost_GBP]] > Analysis_Sheet!$B$21, "Above Average", "Within Average") -> Above Average | N2: =IF(ISNUMBER(F2),TEXT(F2,"MMMM YYYY"),"Unknown") -> December 2024
A3: P1158 | B3: 95 | C3: FEMALE | D3: Kidney Disease | E3: Keele Hospital | F3: 45621 | G3: 12 | H3: 1002.0676 | I3: Recovered | J3: {=_xlfn.IFS(Table3[[#This Row],[Age (Years)]] < 40, "Young", Table3[[#This Row],[Age (Years)]] >= 40, "Middle", Table3[[#This Row],[Age (Years)]] > 60, "Senior")} -> Middle | K3: {=_xlfn.IFS(Table3[[#This Row],[Drug_Cost_GBP]] > 1200, "High Cost", Table3[[#This Row],[Drug_Cost_GBP]] < 1200, "Normal")} -> Normal | L3: {=IFERROR(_xlfn.IFS(Table3[[#This Row],[Age (Years)]] > 75, "YES", Table3[[#This Row],[Age (Years)]] < 75, "NO"), "UNKNOWN")} -> YES | M3: =IF(Table3[[#This Row],[Drug_Cost_GBP]] > Analysis_Sheet!$B$21, "Above Average", "Within Average") -> Within Average | N3: =IF(ISNUMBER(F3),TEXT(F3,"MMMM YYYY"),"Unknown") -> November 2024
A4: P0392 | B4: 95 | C4: FEMALE | D4: Diabetes | E4: Russells Hall Hospital | F4: 45467 | G4: 19 | H4: 490.75 | I4: Unknown | J4: {=_xlfn.IFS(Table3[[#This Row],[Age (Years)]] < 40, "Young", Table3[[#This Row],[Age (Years)]] >= 40, "Middle", Table3[[#This Row],[Age (Years)]] > 60, "Senior")} -> Middle | K4: {=_xlfn.IFS(Table3[[#This Row],[Drug_Cost_GBP]] > 1200, "High Cost", Table3[[#This Row],[Drug_Cost_GBP]] < 1200, "Normal")} -> Normal | L4: {=IFERROR(_xlfn.IFS(Table3[[#This Row],[Age (Years)]] > 75, "YES", Table3[[#This Row],[Age (Years)]] < 75, "NO"), "UNKNOWN")} -> YES | M4: =IF(Table3[[#This Row],[Drug_Cost_GBP]] > Analysis_Sheet!$B$21, "Above Average", "Within Average") -> Within Average | N4: =IF(ISNUMBER(F4),TEXT(F4,"MMMM YYYY"),"Unknown") -> June 2024
A5: P0754 | B5: 95 | C5: FEMALE | D5: Stroke | E5: Stoke Hospital | F5: Unknown | G5: 12 | H5: 1002.0676 | I5: Ongoing | J5: {=_xlfn.IFS(Table3[[#This Row],[Age (Years)]] < 40, "Young", Table3[[#This Row],[Age (Years)]] >= 40, "Middle", Table3[[#This Row],[Age (Years)]] > 60, "Senior")} -> Middle | K5: {=_xlfn.IFS(Table3[[#This Row],[Drug_Cost_GBP]] > 1200, "High Cost", Table3[[#This Row],[Drug_Cost_GBP]] < 1200, "Normal")} -> Normal | L5: {=IFERROR(_xlfn.IFS(Table3[[#This Row],[Age (Years)]] > 75, "YES", Table3[[#This Row],[Age (Years)]] < 75, "NO"), "UNKNOWN")} -> YES | M5: =IF(Table3[[#This Row],[Drug_Cost_GBP]] > Analysis_Sheet!$B$21, "Above Average", "Within Average") -> Within Average | N5: =IF(ISNUMBER(F5),TEXT(F5,"MMMM YYYY"),"Unknown") -> Unknown
A6: P0319 | B6: 95 | C6: FEMALE | D6: Stroke | E6: New Cross Hospital | F6: 45616 | G6: 12 | H6: 1410.32 | I6: Unknown | J6: {=_xlfn.IFS(Table3[[#This Row],[Age (Years)]] < 40, "Young", Table3[[#This Row],[Age (Years)]] >= 40, "Middle", Table3[[#This Row],[Age (Years)]] > 60, "Senior")} -> Middle | K6: {=_xlfn.IFS(Table3[[#This Row],[Drug_Cost_GBP]] > 1200, "High Cost", Table3[[#This Row],[Drug_Cost_GBP]] < 1200, "Normal")} -> High Cost | L6: {=IFERROR(_xlfn.IFS(Table3[[#This Row],[Age (Years)]] > 75, "YES", Table3[[#This Row],[Age (Years)]] < 75, "NO"), "UNKNOWN")} -> YES | M6: =IF(Table3[[#This Row],[Drug_Cost_GBP]] > Analysis_Sheet!$B$21, "Above Average", "Within Average") -> Above Average | N6: =IF(ISNUMBER(F6),TEXT(F6,"MMMM YYYY"),"Unknown") -> November 2024
A7: P0874 | B7: 95 | C7: Unknown | D7: Copd | E7: New Cross Hospital | F7: Unknown | G7: 12 | H7: 1181.22 | I7: Unknown | J7: {=_xlfn.IFS(Table3[[#This Row],[Age (Years)]] < 40, "Young", Table3[[#This Row],[Age (Years)]] >= 40, "Middle", Table3[[#This Row],[Age (Years)]] > 60, "Senior")} -> Middle | K7: {=_xlfn.IFS(Table3[[#This Row],[Drug_Cost_GBP]] > 1200, "High Cost", Table3[[#This Row],[Drug_Cost_GBP]] < 1200, "Normal")} -> Normal | L7: {=IFERROR(_xlfn.IFS(Table3[[#This Row],[Age (Years)]] > 75, "YES", Table3[[#This Row],[Age (Years)]] < 75, "NO"), "UNKNOWN")} -> YES | M7: =IF(Table3[[#This Row],[Drug_Cost_GBP]] > Analysis_Sheet!$B$21, "Above Average", "Within Average") -> Above Average | N7: =IF(ISNUMBER(F7),TEXT(F7,"MMMM YYYY"),"Unknown") -> Unknown
A8: P1064 | B8: 94 | C8: FEMALE | D8: Asthma | E8: New Cross Hospital | F8: Unknown | G8: 12 | H8: 903.44 | I8: Recovered | J8: {=_xlfn.IFS(Table3[[#This Row],[Age (Years)]] < 40, "Young", Table3[[#This Row],[Age (Years)]] >= 40, "Middle", Table3[[#This Row],[Age (Years)]] > 60, "Senior")} -> Middle | K8: {=_xlfn.IFS(Table3[[#This Row],[Drug_Cost_GBP]] > 1200, "High Cost", Table3[[#This Row],[Drug_Cost_GBP]] < 1200, "Normal")} -> Normal | L8: {=IFERROR(_xlfn.IFS(Table3[[#This Row],[Age (Years)]] > 75, "YES", Table3[[#This Row],[Age (Years)]] < 75, "NO"), "UNKNOWN")} -> YES | M8: =IF(Table3[[#This Row],[Drug_Cost_GBP]] > Analysis_Sheet!$B$21, "Above Average", "Within Average") -> Within Average | N8: =IF(ISNUMBER(F8),TEXT(F8,"MMMM YYYY"),"Unknown") -> Unknown
A9: P1118 | B9: 94 | C9: FEMALE | D9: Copd | E9: Stoke Hospital | F9: 45356 | G9: 12 | H9: 851.41 | I9: Recovered | J9: {=_xlfn.IFS(Table3[[#This Row],[Age (Years)]] < 40, "Young", Table3[[#This Row],[Age (Years)]] >= 40, "Middle", Table3[[#This Row],[Age (Years)]] > 60, "Senior")} -> Middle | K9: {=_xlfn.IFS(Table3[[#This Row],[Drug_Cost_GBP]] > 1200, "High Cost", Table3[[#This Row],[Drug_Cost_GBP]] < 1200, "Normal")} -> Normal | L9: {=IFERROR(_xlfn.IFS(Table3[[#This Row],[Age (Years)]] > 75, "YES", Table3[[#This Row],[Age (Years)]] < 75, "NO"), "UNKNOWN")} -> YES | M9: =IF(Table3[[#This Row],[Drug_Cost_GBP]] > Analysis_Sheet!$B$21, "Above Average", "Within Average") -> Within Average | N9: =IF(ISNUMBER(F9),TEXT(F9,"MMMM YYYY"),"Unknown") -> March 2024
A10: P0999 | B10: 94 | C10: MALE | D10: Heart Disease | E10: New Cross Hospital | F10: 45524 | G10: 12 | H10: 1809.21 | I10: Unknown | J10: {=_xlfn.IFS(Table3[[#This Row],[Age (Years)]] < 40, "Young", Table3[[#This Row],[Age (Years)]] >= 40, "Middle", Table3[[#This Row],[Age (Years)]] > 60, "Senior")} -> Middle | K10: {=_xlfn.IFS(Table3[[#This Row],[Drug_Cost_GBP]] > 1200, "High Cost", Table3[[#This Row],[Drug_Cost_GBP]] < 1200, "Normal")} -> High Cost | L10: {=IFERROR(_xlfn.IFS(Table3[[#This Row],[Age (Years)]] > 75, "YES", Table3[[#This Row],[Age (Years)]] < 75, "NO"), "UNKNOWN")} -> YES | M10: =IF(Table3[[#This Row],[Drug_Cost_GBP]] > Analysis_Sheet!$B$21, "Above Average", "Within Average") -> Above Average | N10: =IF(ISNUMBER(F10),TEXT(F10,"MMMM YYYY"),"Unknown") -> August 2024
A11: P0749 | B11: 93 | C11: Unknown | D11: Copd | E11: Walsall Manor | F11: 45500 | G11: 12 | H11: 1202.99 | I11: Unknown | J11: {=_xlfn.IFS(Table3[[#This Row],[Age (Years)]] < 40, "Young", Table3[[#This Row],[Age (Years)]] >= 40, "Middle", Table3[[#This Row],[Age (Years)]] > 60, "Senior")} -> Middle | K11: {=_xlfn.IFS(Table3[[#This Row],[Drug_Cost_GBP]] > 1200, "High Cost", Table3[[#This Row],[Drug_Cost_GBP]] < 1200, "Normal")} -> High Cost | L11: {=IFERROR(_xlfn.IFS(Table3[[#This Row],[Age (Years)]] > 75, "YES", Table3[[#This Row],[Age (Years)]] < 75, "NO"), "UNKNOWN")} -> YES | M11: =IF(Table3[[#This Row],[Drug_Cost_GBP]] > Analysis_Sheet!$B$21, "Above Average", "Within Average") -> Above Average | N11: =IF(ISNUMBER(F11),TEXT(F11,"MMMM YYYY"),"Unknown") -> July 2024
A12: P0191 | B12: 93 | C12: Unknown | D12: Copd | E12: Stoke Hospital | F12: 45307 | G12: 3 | H12: 1081.83 | I12: Referred | J12: {=_xlfn.IFS(Table3[[#This Row],[Age (Years)]] < 40, "Young", Table3[[#This Row],[Age (Years)]] >= 40, "Middle", Table3[[#This Row],[Age (Years)]] > 60, "Senior")} -> Middle | K12: {=_xlfn.IFS(Table3[[#This Row],[Drug_Cost_GBP]] > 1200, "High Cost", Table3[[#This Row],[Drug_Cost_GBP]] < 1200, "Normal")} -> Normal | L12: {=IFERROR(_xlfn.IFS(Table3[[#This Row],[Age (Years)]] > 75, "YES", Table3[[#This Row],[Age (Years)]] < 75, "NO"), "UNKNOWN")} -> YES | M12: =IF(Table3[[#This Row],[Drug_Cost_GBP]] > Analysis_Sheet!$B$21, "Above Average", "Within Average") -> Above Average | N12: =IF(ISNUMBER(F12),TEXT(F12,"MMMM YYYY"),"Unknown") -> January 2024
A13: P0634 | B13: 93 | C13: MALE | D13: Stroke | E13: New Cross Hospital | F13: Unknown | G13: 12 | H13: 877.29 | I13: Deceased | J13: {=_xlfn.IFS(Table3[[#This Row],[Age (Years)]] < 40, "Young", Table3[[#This Row],[Age (Years)]] >= 40, "Middle", Table3[[#This Row],[Age (Years)]] > 60, "Senior")} -> Middle | K13: {=_xlfn.IFS(Table3[[#This Row],[Drug_Cost_GBP]] > 1200, "High Cost", Table3[[#This Row],[Drug_Cost_GBP]] < 1200, "Normal")} -> Normal | L13: {=IFERROR(_xlfn.IFS(Table3[[#This Row],[Age (Years)]] > 75, "YES", Table3[[#This Row],[Age (Years)]] < 75, "NO"), "UNKNOWN")} -> YES | M13: =IF(Table3[[#This Row],[Drug_Cost_GBP]] > Analysis_Sheet!$B$21, "Above Average", "Within Average") -> Within Average | N13: =IF(ISNUMBER(F13),TEXT(F13,"MMMM YYYY"),"Unknown") -> Unknown
A14: P0237 | B14: 92 | C14: MALE | D14: Heart Disease | E14: New Cross Hospital | F14: 45486 | G14: 20 | H14: 1002.0676 | I14: Unknown | J14: {=_xlfn.IFS(Table3[[#This Row],[Age (Years)]] < 40, "Young", Table3[[#This Row],[Age (Years)]] >= 40, "Middle", Table3[[#This Row],[Age (Years)]] > 60, "Senior")} -> Middle | K14: {=_xlfn.IFS(Table3[[#This Row],[Drug_Cost_GBP]] > 1200, "High Cost", Table3[[#This Row],[Drug_Cost_GBP]] < 1200, "Normal")} -> Normal | L14: {=IFERROR(_xlfn.IFS(Table3[[#This Row],[Age (Years)]] > 75, "YES", Table3[[#This Row],[Age (Years)]] < 75, "NO"), "UNKNOWN")} -> YES | M14: =IF(Table3[[#This Row],[Drug_Cost_GBP]] > Analysis_Sheet!$B$21, "Above Average", "Within Average") -> Within Average | N14: =IF(ISNUMBER(F14),TEXT(F14,"MMMM YYYY"),"Unknown") -> July 2024
A15: P0680 | B15: 92 | C15: MALE | D15: Heart Disease | E15: Walsall Manor | F15: 45426 | G15: 12 | H15: 1002.0676 | I15: Recovered | J15: {=_xlfn.IFS(Table3[[#This Row],[Age (Years)]] < 40, "Young", Table3[[#This Row],[Age (Years)]] >= 40, "Middle", Table3[[#This Row],[Age (Years)]] > 60, "Senior")} -> Middle | K15: {=_xlfn.IFS(Table3[[#This Row],[Drug_Cost_GBP]] > 1200, "High Cost", Table3[[#This Row],[Drug_Cost_GBP]] < 1200, "Normal")} -> Normal | L15: {=IFERROR(_xlfn.IFS(Table3[[#This Row],[Age (Years)]] > 75, "YES", Table3[[#This Row],[Age (Years)]] < 75, "NO"), "UNKNOWN")} -> YES | M15: =IF(Table3[[#This Row],[Drug_Cost_GBP]] > Analysis_Sheet!$B$21, "Above Average", "Within Average") -> Within Average | N15: =IF(ISNUMBER(F15),TEXT(F15,"MMMM YYYY"),"Unknown") -> May 2024
A16: P0925 | B16: 92 | C16: MALE | D16: Copd | E16: Stafford Hospital | F16: 45351 | G16: 12 | H16: 450.32 | I16: Referred | J16: {=_xlfn.IFS(Table3[[#This Row],[Age (Years)]] < 40, "Young", Table3[[#This Row],[Age (Years)]] >= 40, "Middle", Table3[[#This Row],[Age (Years)]] > 60, "Senior")} -> Middle | K16: {=_xlfn.IFS(Table3[[#This Row],[Drug_Cost_GBP]] > 1200, "High Cost", Table3[[#This Row],[Drug_Cost_GBP]] < 1200, "Normal")} -> Normal | L16: {=IFERROR(_xlfn.IFS(Table3[[#This Row],[Age (Years)]] > 75, "YES", Table3[[#This Row],[Age (Years)]] < 75, "NO"), "UNKNOWN")} -> YES | M16: =IF(Table3[[#This Row],[Drug_Cost_GBP]] > Analysis_Sheet!$B$21, "Above Average", "Within Average") -> Within Average | N16: =IF(ISNUMBER(F16),TEXT(F16,"MMMM YYYY"),"Unknown") -> February 2024
A17: P0178 | B17: 92 | C17: Unknown | D17: Copd | E17: Stoke Hospital | F17: 45587 | G17: 12 | H17: 1002.0676 | I17: Unknown | J17: {=_xlfn.IFS(Table3[[#This Row],[Age (Years)]] < 40, "Young", Table3[[#This Row],[Age (Years)]] >= 40, "Middle", Table3[[#This Row],[Age (Years)]] > 60, "Senior")} -> Middle | K17: {=_xlfn.IFS(Table3[[#This Row],[Drug_Cost_GBP]] > 1200, "High Cost", Table3[[#This Row],[Drug_Cost_GBP]] < 1200, "Normal")} -> Normal | L17: {=IFERROR(_xlfn.IFS(Table3[[#This Row],[Age (Years)]] > 75, "YES", Table3[[#This Row],[Age (Years)]] < 75, "NO"), "UNKNOWN")} -> YES | M17: =IF(Table3[[#This Row],[Drug_Cost_GBP]] > Analysis_Sheet!$B$21, "Above Average", "Within Average") -> Within Average | N17: =IF(ISNUMBER(F17),TEXT(F17,"MMMM YYYY"),"Unknown") -> October 2024
A18: P0020 | B18: 91 | C18: Unknown | D18: Copd | E18: Walsall Manor | F18: 45600 | G18: 2 | H18: 1002.0676 | I18: Recovered | J18: {=_xlfn.IFS(Table3[[#This Row],[Age (Years)]] < 40, "Young", Table3[[#This Row],[Age (Years)]] >= 40, "Middle", Table3[[#This Row],[Age (Years)]] > 60, "Senior")} -> Middle | K18: {=_xlfn.IFS(Table3[[#This Row],[Drug_Cost_GBP]] > 1200, "High Cost", Table3[[#This Row],[Drug_Cost_GBP]] < 1200, "Normal")} -> Normal | L18: {=IFERROR(_xlfn.IFS(Table3[[#This Row],[Age (Years)]] > 75, "YES", Table3[[#This Row],[Age (Years)]] < 75, "NO"), "UNKNOWN")} -> YES | M18: =IF(Table3[[#This Row],[Drug_Cost_GBP]] > Analysis_Sheet!$B$21, "Above Average", "Within Average") -> Within Average | N18: =IF(ISNUMBER(F18),TEXT(F18,"MMMM YYYY"),"Unknown") -> November 2024
A19: P0366 | B19: 91 | C19: FEMALE | D19: Asthma | E19: Stafford Hospital | F19: Unknown | G19: 12 | H19: 1744.92 | I19: Recovered | J19: {=_xlfn.IFS(Table3[[#This Row],[Age (Years)]] < 40, "Young", Table3[[#This Row],[Age (Years)]] >= 40, "Middle", Table3[[#This Row],[Age (Years)]] > 60, "Senior")} -> Middle | K19: {=_xlfn.IFS(Table3[[#This Row],[Drug_Cost_GBP]] > 1200, "High Cost", Table3[[#This Row],[Drug_Cost_GBP]] < 1200, "Normal")} -> High Cost | L19: {=IFERROR(_xlfn.IFS(Table3[[#This Row],[Age (Years)]] > 75, "YES", Table3[[#This Row],[Age (Years)]] < 75, "NO"), "UNKNOWN")} -> YES | M19: =IF(Table3[[#This Row],[Drug_Cost_GBP]] > Analysis_Sheet!$B$21, "Above Average", "Within Average") -> Above Average | N19: =IF(ISNUMBER(F19),TEXT(F19,"MMMM YYYY"),"Unknown") -> Unknown
A20: P0827 | B20: 91 | C20: FEMALE | D20: Stroke | E20: Stafford Hospital | F20: Unknown | G20: 16 | H20: 1002.0676 | I20: Unknown | J20: {=_xlfn.IFS(Table3[[#This Row],[Age (Years)]] < 40, "Young", Table3[[#This Row],[Age (Years)]] >= 40, "Middle", Table3[[#This Row],[Age (Years)]] > 60, "Senior")} -> Middle | K20: {=_xlfn.IFS(Table3[[#This Row],[Drug_Cost_GBP]] > 1200, "High Cost", Table3[[#This Row],[Drug_Cost_GBP]] < 1200, "Normal")} -> Normal | L20: {=IFERROR(_xlfn.IFS(Table3[[#This Row],[Age (Years)]] > 75, "YES", Table3[[#This Row],[Age (Years)]] < 75, "NO"), "UNKNOWN")} -> YES | M20: =IF(Table3[[#This Row],[Drug_Cost_GBP]] > Analysis_Sheet!$B$21, "Above Average", "Within Average") -> Within Average | N20: =IF(ISNUMBER(F20),TEXT(F20,"MMMM YYYY"),"Unknown") -> Unknown
A21: P0221 | B21: 91 | C21: FEMALE | D21: Hypertension | E21: New Cross Hospital | F21: 45521 | G21: 12 | H21: 787.12 | I21: Deceased | J21: {=_xlfn.IFS(Table3[[#This Row],[Age (Years)]] < 40, "Young", Table3[[#This Row],[Age (Years)]] >= 40, "Middle", Table3[[#This Row],[Age (Years)]] > 60, "Senior")} -> Middle | K21: {=_xlfn.IFS(Table3[[#This Row],[Drug_Cost_GBP]] > 1200, "High Cost", Table3[[#This Row],[Drug_Cost_GBP]] < 1200, "Normal")} -> Normal | L21: {=IFERROR(_xlfn.IFS(Table3[[#This Row],[Age (Years)]] > 75, "YES", Table3[[#This Row],[Age (Years)]] < 75, "NO"), "UNKNOWN")} -> YES | M21: =IF(Table3[[#This Row],[Drug_Cost_GBP]] > Analysis_Sheet!$B$21, "Above Average", "Within Average") -> Within Average | N21: =IF(ISNUMBER(F21),TEXT(F21,"MMMM YYYY"),"Unknown") -> August 2024
A22: P0218 | B22: 89 | C22: MALE | D22: Copd | E22: Walsall Manor | F22: 45380 | G22: 12 | H22: 502.99 | I22: Ongoing | J22: {=_xlfn.IFS(Table3[[#This Row],[Age (Years)]] < 40, "Young", Table3[[#This Row],[Age (Years)]] >= 40, "Middle", Table3[[#This Row],[Age (Years)]] > 60, "Senior")} -> Middle | K22: {=_xlfn.IFS(Table3[[#This Row],[Drug_Cost_GBP]] > 1200, "High Cost", Table3[[#This Row],[Drug_Cost_GBP]] < 1200, "Normal")} -> Normal | L22: {=IFERROR(_xlfn.IFS(Table3[[#This Row],[Age (Years)]] > 75, "YES", Table3[[#This Row],[Age (Years)]] < 75, "NO"), "UNKNOWN")} -> YES | M22: =IF(Table3[[#This Row],[Drug_Cost_GBP]] > Analysis_Sheet!$B$21, "Above Average", "Within Average") -> Within Average | N22: =IF(ISNUMBER(F22),TEXT(F22,"MMMM YYYY"),"Unknown") -> March 2024
A23: P1190 | B23: 88 | C23: FEMALE | D23: Heart Disease | E23: Stoke Hospital | F23: 45381 | G23: 6 | H23: 1002.0676 | I23: Unknown | J23: {=_xlfn.IFS(Table3[[#This Row],[Age (Years)]] < 40, "Young", Table3[[#This Row],[Age (Years)]] >= 40, "Middle", Table3[[#This Row],[Age (Years)]] > 60, "Senior")} -> Middle | K23: {=_xlfn.IFS(Table3[[#This Row],[Drug_Cost_GBP]] > 1200, "High Cost", Table3[[#This Row],[Drug_Cost_GBP]] < 1200, "Normal")} -> Normal | L23: {=IFERROR(_xlfn.IFS(Table3[[#This Row],[Age (Years)]] > 75, "YES", Table3[[#This Row],[Age (Years)]] < 75, "NO"), "UNKNOWN")} -> YES | M23: =IF(Table3[[#This Row],[Drug_Cost_GBP]] > Analysis_Sheet!$B$21, "Above Average", "Within Average") -> Within Average | N23: =IF(ISNUMBER(F23),TEXT(F23,"MMMM YYYY"),"Unknown") -> March 2024
A24: P0583 | B24: 88 | C24: MALE | D24: Kidney Disease | E24: New Cross Hospital | F24: Unknown | G24: 12 | H24: 879.82 | I24: Deceased | J24: {=_xlfn.IFS(Table3[[#This Row],[Age (Years)]] < 40, "Young", Table3[[#This Row],[Age (Years)]] >= 40, "Middle", Table3[[#This Row],[Age (Years)]] > 60, "Senior")} -> Middle | K24: {=_xlfn.IFS(Table3[[#This Row],[Drug_Cost_GBP]] > 1200, "High Cost", Table3[[#This Row],[Drug_Cost_GBP]] < 1200, "Normal")} -> Normal | L24: {=IFERROR(_xlfn.IFS(Table3[[#This Row],[Age (Years)]] > 75, "YES", Table3[[#This Row],[Age (Years)]] < 75, "NO"), "UNKNOWN")} -> YES | M24: =IF(Table3[[#This Row],[Drug_Cost_GBP]] > Analysis_Sheet!$B$21, "Above Average", "Within Average") -> Within Average | N24: =IF(ISNUMBER(F24),TEXT(F24,"MMMM YYYY"),"Unknown") -> Unknown
A25: P0931 | B25: 87 | C25: MALE | D25: Diabetes | E25: Keele Hospital | F25: 45491 | G25: 12 | H25: 387.49 | I25: Unknown | J25: {=_xlfn.IFS(Table3[[#This Row],[Age (Years)]] < 40, "Young", Table3[[#This Row],[Age (Years)]] >= 40, "Middle", Table3[[#This Row],[Age (Years)]] > 60, "Senior")} -> Middle | K25: {=_xlfn.IFS(Table3[[#This Row],[Drug_Cost_GBP]] > 1200, "High Cost", Table3[[#This Row],[Drug_Cost_GBP]] < 1200, "Normal")} -> Normal | L25: {=IFERROR(_xlfn.IFS(Table3[[#This Row],[Age (Years)]] > 75, "YES", Table3[[#This Row],[Age (Years)]] < 75, "NO"), "UNKNOWN")} -> YES | M25: =IF(Table3[[#This Row],[Drug_Cost_GBP]] > Analysis_Sheet!$B$21, "Above Average", "Within Average") -> Within Average | N25: =IF(ISNUMBER(F25),TEXT(F25,"MMMM YYYY"),"Unknown") -> July 2024
A26: P0443 | B26: 87 | C26: Unknown | D26: Asthma | E26: New Cross Hospital | F26: 45477 | G26: 12 | H26: 1002.0676 | I26: Recovered | J26: {=_xlfn.IFS(Table3[[#This Row],[Age (Years)]] < 40, "Young", Table3[[#This Row],[Age (Years)]] >= 40, "Middle", Table3[[#This Row],[Age (Years)]] > 60, "Senior")} -> Middle | K26: {=_xlfn.IFS(Table3[[#This Row],[Drug_Cost_GBP]] > 1200, "High Cost", Table3[[#This Row],[Drug_Cost_GBP]] < 1200, "Normal")} -> Normal | L26: {=IFERROR(_xlfn.IFS(Table3[[#This Row],[Age (Years)]] > 75, "YES", Table3[[#This Row],[Age (Years)]] < 75, "NO"), "UNKNOWN")} -> YES | M26: =IF(Table3[[#This Row],[Drug_Cost_GBP]] > Analysis_Sheet!$B$21, "Above Average", "Within Average") -> Within Average | N26: =IF(ISNUMBER(F26),TEXT(F26,"MMMM YYYY"),"Unknown") -> July 2024
A27: P0893 | B27: 87 | C27: Unknown | D27: Heart Disease | E27: Stafford Hospital | F27: 45331 | G27: 5 | H27: 791.73 | I27: Recovered | J27: {=_xlfn.IFS(Table3[[#This Row],[Age (Years)]] < 40, "Young", Table3[[#This Row],[Age (Years)]] >= 40, "Middle", Table3[[#This Row],[Age (Years)]] > 60, "Senior")} -> Middle | K27: {=_xlfn.IFS(Table3[[#This Row],[Drug_Cost_GBP]] > 1200, "High Cost", Table3[[#This Row],[Drug_Cost_GBP]] < 1200, "Normal")} -> Normal | L27: {=IFERROR(_xlfn.IFS(Table3[[#This Row],[Age (Years)]] > 75, "YES", Table3[[#This Row],[Age (Years)]] < 75, "NO"), "UNKNOWN")} -> YES | M27: =IF(Table3[[#This Row],[Drug_Cost_GBP]] > Analysis_Sheet!$B$21, "Above Average", "Within Average") -> Within Average | N27: =IF(ISNUMBER(F27),TEXT(F27,"MMMM YYYY"),"Unknown") -> February 2024
A28: P0389 | B28: 87 | C28: MALE | D28: Asthma | E28: New Cross Hospital | F28: 45515 | G28: 10 | H28: 1002.0676 | I28: Unknown | J28: {=_xlfn.IFS(Table3[[#This Row],[Age (Years)]] < 40, "Young", Table3[[#This Row],[Age (Years)]] >= 40, "Middle", Table3[[#This Row],[Age (Years)]] > 60, "Senior")} -> Middle | K28: {=_xlfn.IFS(Table3[[#This Row],[Drug_Cost_GBP]] > 1200, "High Cost", Table3[[#This Row],[Drug_Cost_GBP]] < 1200, "Normal")} -> Normal | L28: {=IFERROR(_xlfn.IFS(Table3[[#This Row],[Age (Years)]] > 75, "YES", Table3[[#This Row],[Age (Years)]] < 75, "NO"), "UNKNOWN")} -> YES | M28: =IF(Table3[[#This Row],[Drug_Cost_GBP]] > Analysis_Sheet!$B$21, "Above Average", "Within Average") -> Within Average | N28: =IF(ISNUMBER(F28),TEXT(F28,"MMMM YYYY"),"Unknown") -> August 2024
A29: P0411 | B29: 87 | C29: MALE | D29: Kidney Disease | E29: Russells Hall Hospital | F29: Unknown | G29: 12 | H29: 1002.0676 | I29: Recovered | J29: {=_xlfn.IFS(Table3[[#This Row],[Age (Years)]] < 40, "Young", Table3[[#This Row],[Age (Years)]] >= 40, "Middle", Table3[[#This Row],[Age (Years)]] > 60, "Senior")} -> Middle | K29: {=_xlfn.IFS(Table3[[#This Row],[Drug_Cost_GBP]] > 1200, "High Cost", Table3[[#This Row],[Drug_Cost_GBP]] < 1200, "Normal")} -> Normal | L29: {=IFERROR(_xlfn.IFS(Table3[[#This Row],[Age (Years)]] > 75, "YES", Table3[[#This Row],[Age (Years)]] < 75, "NO"), "UNKNOWN")} -> YES | M29: =IF(Table3[[#This Row],[Drug_Cost_GBP]] > Analysis_Sheet!$B$21, "Above Average", "Within Average") -> Within Average | N29: =IF(ISNUMBER(F29),TEXT(F29,"MMMM YYYY"),"Unknown") -> Unknown
A30: P0035 | B30: 87 | C30: Unknown | D30: Hypertension | E30: New Cross Hospital | F30: 45593 | G30: 12 | H30: 1002.0676 | I30: Deceased | J30: {=_xlfn.IFS(Table3[[#This Row],[Age (Years)]] < 40, "Young", Table3[[#This Row],[Age (Years)]] >= 40, "Middle", Table3[[#This Row],[Age (Years)]] > 60, "Senior")} -> Middle | K30: {=_xlfn.IFS(Table3[[#This Row],[Drug_Cost_GBP]] > 1200, "High Cost", Table3[[#This Row],[Drug_Cost_GBP]] < 1200, "Normal")} -> Normal | L30: {=IFERROR(_xlfn.IFS(Table3[[#This Row],[Age (Years)]] > 75, "YES", Table3[[#This Row],[Age (Years)]] < 75, "NO"), "UNKNOWN")} -> YES | M30: =IF(Table3[[#This Row],[Drug_Cost_GBP]] > Analysis_Sheet!$B$21, "Above Average", "Within Average") -> Within Average | N30: =IF(ISNUMBER(F30),TEXT(F30,"MMMM YYYY"),"Unknown") -> October 2024
A31: P0232 | B31: 87 | C31: MALE | D31: Hypertension | E31: Walsall Manor | F31: Unknown | G31: 12 | H31: 1002.0676 | I31: Recovered | J31: {=_xlfn.IFS(Table3[[#This Row],[Age (Years)]] < 40, "Young", Table3[[#This Row],[Age (Years)]] >= 40, "Middle", Table3[[#This Row],[Age (Years)]] > 60, "Senior")} -> Middle | K31: {=_xlfn.IFS(Table3[[#This Row],[Drug_Cost_GBP]] > 1200, "High Cost", Table3[[#This Row],[Drug_Cost_GBP]] < 1200, "Normal")} -> Normal | L31: {=IFERROR(_xlfn.IFS(Table3[[#This Row],[Age (Years)]] > 75, "YES", Table3[[#This Row],[Age (Years)]] < 75, "NO"), "UNKNOWN")} -> YES | M31: =IF(Table3[[#This Row],[Drug_Cost_GBP]] > Analysis_Sheet!$B$21, "Above Average", "Within Average") -> Within Average | N31: =IF(ISNUMBER(F31),TEXT(F31,"MMMM YYYY"),"Unknown") -> Unknown
A32: P1037 | B32: 86 | C32: Unknown | D32: Asthma | E32: New Cross Hospital | F32: 45332 | G32: 16 | H32: 1002.0676 | I32: Recovered | J32: {=_xlfn.IFS(Table3[[#This Row],[Age (Years)]] < 40, "Young", Table3[[#This Row],[Age (Years)]] >= 40, "Middle", Table3[[#This Row],[Age (Years)]] > 60, "Senior")} -> Middle | K32: {=_xlfn.IFS(Table3[[#This Row],[Drug_Cost_GBP]] > 1200, "High Cost", Table3[[#This Row],[Drug_Cost_GBP]] < 1200, "Normal")} -> Normal | L32: {=IFERROR(_xlfn.IFS(Table3[[#This Row],[Age (Years)]] > 75, "YES", Table3[[#This Row],[Age (Years)]] < 75, "NO"), "UNKNOWN")} -> YES | M32: =IF(Table3[[#This Row],[Drug_Cost_GBP]] > Analysis_Sheet!$B$21, "Above Average", "Within Average") -> Within Average | N32: =IF(ISNUMBER(F32),TEXT(F32,"MMMM YYYY"),"Unknown") -> February 2024
A33: P1039 | B33: 86 | C33: FEMALE | D33: Kidney Disease | E33: Keele Hospital | F33: 45600 | G33: 12 | H33: 147.23 | I33: Unknown | J33: {=_xlfn.IFS(Table3[[#This Row],[Age (Years)]] < 40, "Young", Table3[[#This Row],[Age (Years)]] >= 40, "Middle", Table3[[#This Row],[Age (Years)]] > 60, "Senior")} -> Middle | K33: {=_xlfn.IFS(Table3[[#This Row],[Drug_Cost_GBP]] > 1200, "High Cost", Table3[[#This Row],[Drug_Cost_GBP]] < 1200, "Normal")} -> Normal | L33: {=IFERROR(_xlfn.IFS(Table3[[#This Row],[Age (Years)]] > 75, "YES", Table3[[#This Row],[Age (Years)]] < 75, "NO"), "UNKNOWN")} -> YES | M33: =IF(Table3[[#This Row],[Drug_Cost_GBP]] > Analysis_Sheet!$B$21, "Above Average", "Within Average") -> Within Average | N33: =IF(ISNUMBER(F33),TEXT(F33,"MMMM YYYY"),"Unknown") -> November 2024
A34: P0303 | B34: 86 | C34: MALE | D34: Copd | E34: Keele Hospital | F34: 45457 | G34: 12 | H34: 1002.0676 | I34: Deceased | J34: {=_xlfn.IFS(Table3[[#This Row],[Age (Years)]] < 40, "Young", Table3[[#This Row],[Age (Years)]] >= 40, "Middle", Table3[[#This Row],[Age (Years)]] > 60, "Senior")} -> Middle | K34: {=_xlfn.IFS(Table3[[#This Row],[Drug_Cost_GBP]] > 1200, "High Cost", Table3[[#This Row],[Drug_Cost_GBP]] < 1200, "Normal")} -> Normal | L34: {=IFERROR(_xlfn.IFS(Table3[[#This Row],[Age (Years)]] > 75, "YES", Table3[[#This Row],[Age (Years)]] < 75, "NO"), "UNKNOWN")} -> YES | M34: =IF(Table3[[#This Row],[Drug_Cost_GBP]] > Analysis_Sheet!$B$21, "Above Average", "Within Average") -> Within Average | N34: =IF(ISNUMBER(F34),TEXT(F34,"MMMM YYYY"),"Unknown") -> June 2024
A35: P0974 | B35: 85 | C35: Unknown | D35: Unknown | E35: New Cross Hospital | F35: 45598 | G35: 12 | H35: 963.47 | I35: Unknown | J35: {=_xlfn.IFS(Table3[[#This Row],[Age (Years)]] < 40, "Young", Table3[[#This Row],[Age (Years)]] >= 40, "Middle", Table3[[#This Row],[Age (Years)]] > 60, "Senior")} -> Middle | K35: {=_xlfn.IFS(Table3[[#This Row],[Drug_Cost_GBP]] > 1200, "High Cost", Table3[[#This Row],[Drug_Cost_GBP]] < 1200, "Normal")} -> Normal | L35: {=IFERROR(_xlfn.IFS(Table3[[#This Row],[Age (Years)]] > 75, "YES", Table3[[#This Row],[Age (Years)]] < 75, "NO"), "UNKNOWN")} -> YES | M35: =IF(Table3[[#This Row],[Drug_Cost_GBP]] > Analysis_Sheet!$B$21, "Above Average", "Within Average") -> Within Average | N35: =IF(ISNUMBER(F35),TEXT(F35,"MMMM YYYY"),"Unknown") -> November 2024
A36: P1011 | B36: 84 | C36: Unknown | D36: Diabetes | E36: New Cross Hospital | F36: 45412 | G36: 12 | H36: 1002.0676 | I36: Recovered | J36: {=_xlfn.IFS(Table3[[#This Row],[Age (Years)]] < 40, "Young", Table3[[#This Row],[Age (Years)]] >= 40, "Middle", Table3[[#This Row],[Age (Years)]] > 60, "Senior")} -> Middle | K36: {=_xlfn.IFS(Table3[[#This Row],[Drug_Cost_GBP]] > 1200, "High Cost", Table3[[#This Row],[Drug_Cost_GBP]] < 1200, "Normal")} -> Normal | L36: {=IFERROR(_xlfn.IFS(Table3[[#This Row],[Age (Years)]] > 75, "YES", Table3[[#This Row],[Age (Years)]] < 75, "NO"), "UNKNOWN")} -> YES | M36: =IF(Table3[[#This Row],[Drug_Cost_GBP]] > Analysis_Sheet!$B$21, "Above Average", "Within Average") -> Within Average | N36: =IF(ISNUMBER(F36),TEXT(F36,"MMMM YYYY"),"Unknown") -> April 2024
A37: P0144 | B37: 84 | C37: MALE | D37: Kidney Disease | E37: Stoke Hospital | F37: Unknown | G37: 12 | H37: 587.36 | I37: Ongoing | J37: {=_xlfn.IFS(Table3[[#This Row],[Age (Years)]] < 40, "Young", Table3[[#This Row],[Age (Years)]] >= 40, "Middle", Table3[[#This Row],[Age (Years)]] > 60, "Senior")} -> Middle | K37: {=_xlfn.IFS(Table3[[#This Row],[Drug_Cost_GBP]] > 1200, "High Cost", Table3[[#This Row],[Drug_Cost_GBP]] < 1200, "Normal")} -> Normal | L37: {=IFERROR(_xlfn.IFS(Table3[[#This Row],[Age (Years)]] > 75, "YES", Table3[[#This Row],[Age (Years)]] < 75, "NO"), "UNKNOWN")} -> YES | M37: =IF(Table3[[#This Row],[Drug_Cost_GBP]] > Analysis_Sheet!$B$21, "Above Average", "Within Average") -> Within Average | N37: =IF(ISNUMBER(F37),TEXT(F37,"MMMM YYYY"),"Unknown") -> Unknown
A38: P0478 | B38: 84 | C38: FEMALE | D38: Heart Disease | E38: New Cross Hospital | F38: 45385 | G38: 12 | H38: 1071.35 | I38: Ongoing | J38: {=_xlfn.IFS(Table3[[#This Row],[Age (Years)]] < 40, "Young", Table3[[#This Row],[Age (Years)]] >= 40, "Middle", Table3[[#This Row],[Age (Years)]] > 60, "Senior")} -> Middle | K38: {=_xlfn.IFS(Table3[[#This Row],[Drug_Cost_GBP]] > 1200, "High Cost", Table3[[#This Row],[Drug_Cost_GBP]] < 1200, "Normal")} -> Normal | L38: {=IFERROR(_xlfn.IFS(Table3[[#This Row],[Age (Years)]] > 75, "YES", Table3[[#This Row],[Age (Years)]] < 75, "NO"), "UNKNOWN")} -> YES | M38: =IF(Table3[[#This Row],[Drug_Cost_GBP]] > Analysis_Sheet!$B$21, "Above Average", "Within Average") -> Above Average | N38: =IF(ISNUMBER(F38),TEXT(F38,"MMMM YYYY"),"Unknown") -> April 2024
A39: P0910 | B39: 83 | C39: Unknown | D39: Stroke | E39: Russells Hall Hospital | F39: 45532 | G39: 12 | H39: 1002.0676 | I39: Referred | J39: {=_xlfn.IFS(Table3[[#This Row],[Age (Years)]] < 40, "Young", Table3[[#This Row],[Age (Years)]] >= 40, "Middle", Table3[[#This Row],[Age (Years)]] > 60, "Senior")} -> Middle | K39: {=_xlfn.IFS(Table3[[#This Row],[Drug_Cost_GBP]] > 1200, "High Cost", Table3[[#This Row],[Drug_Cost_GBP]] < 1200, "Normal")} -> Normal | L39: {=IFERROR(_xlfn.IFS(Table3[[#This Row],[Age (Years)]] > 75, "YES", Table3[[#This Row],[Age (Years)]] < 75, "NO"), "UNKNOWN")} -> YES | M39: =IF(Table3[[#This Row],[Drug_Cost_GBP]] > Analysis_Sheet!$B$21, "Above Average", "Within Average") -> Within Average | N39: =IF(ISNUMBER(F39),TEXT(F39,"MMMM YYYY"),"Unknown") -> August 2024
A40: P0416 | B40: 83 | C40: FEMALE | D40: Asthma | E40: Stafford Hospital | F40: 45609 | G40: 12 | H40: 1002.0676 | I40: Deceased | J40: {=_xlfn.IFS(Table3[[#This Row],[Age (Years)]] < 40, "Young", Table3[[#This Row],[Age (Years)]] >= 40, "Middle", Table3[[#This Row],[Age (Years)]] > 60, "Senior")} -> Middle | K40: {=_xlfn.IFS(Table3[[#This Row],[Drug_Cost_GBP]] > 1200, "High Cost", Table3[[#This Row],[Drug_Cost_GBP]] < 1200, "Normal")} -> Normal | L40: {=IFERROR(_xlfn.IFS(Table3[[#This Row],[Age (Years)]] > 75, "YES", Table3[[#This Row],[Age (Years)]] < 75, "NO"), "UNKNOWN")} -> YES | M40: =IF(Table3[[#This Row],[Drug_Cost_GBP]] > Analysis_Sheet!$B$21, "Above Average", "Within Average") -> Within Average | N40: =IF(ISNUMBER(F40),TEXT(F40,"MMMM YYYY"),"Unknown") -> November 2024
...

Sheet Analysis_Sheet
A2: Count total patients | D2: Count patients per condition | F2: Calculate total cost per condition | G2: Calculate average age per condition
A3: Calculate average age | D3: Kidney Disease | E3: =COUNTIF(Table3[Condition],Cleaned_Data!D2) -> 176 | F3: =SUMIF(Table3[Condition],Analysis_Sheet!D3,Table3[Drug_Cost_GBP]) -> 91073.646 | G3: =AVERAGEIF(Table3[Condition],Analysis_Sheet!D3,Table3[Age (Years)]) -> 56.744681
A4: Find minimum age | D4: Unknown | E4: =COUNTIF(Cleaned_Data!D:D,Cleaned_Data!D12) -> 107 | F4: =SUMIF(Table3[Condition],Analysis_Sheet!D4,Table3[Drug_Cost_GBP]) -> 112260.11 | G4: =AVERAGEIF(Table3[Condition],Analysis_Sheet!D4,Table3[Age (Years)]) -> 55.99115
A5: Find maximum age | D5: Hypertension | E5: =COUNTIF(Cleaned_Data!D:D,Table3[[#This Row],[Condition]]) -> 99 | F5: =SUMIF(Table3[Condition],Analysis_Sheet!D5,Table3[Drug_Cost_GBP]) -> 98783.826 | G5: =AVERAGEIF(Table3[Condition],Analysis_Sheet!D5,Table3[Age (Years)]) -> 56.191919
A6: Calculate total drug cost | D6: Diabetes | E6: =COUNTIF(Table3[Condition],Table3[[#This Row],[Condition]]) -> 99 | F6: =SUMIF(Table3[Condition],Analysis_Sheet!D6,Table3[Drug_Cost_GBP]) -> 179621.85 | G6: =AVERAGEIF(Table3[Condition],Analysis_Sheet!D6,Table3[Age (Years)]) -> 55.409091
A7: Calculate average drug cost | D7: Heart Disease | E7: =COUNTIF(Cleaned_Data!D:D,Cleaned_Data!D8) -> 100 | F7: =SUMIF(Table3[Condition],Analysis_Sheet!D7,Table3[Drug_Cost_GBP]) -> 75629.638 | G7: =AVERAGEIF(Table3[Condition],Analysis_Sheet!D7,Table3[Age (Years)]) -> 58.171053
A8: Count male patients | D8: Asthma | E8: =COUNTIF(Cleaned_Data!D:D,Cleaned_Data!D9) -> 107 | F8: =SUMIF(Table3[Condition],Analysis_Sheet!D8,Table3[Drug_Cost_GBP]) -> 102231.27 | G8: =AVERAGEIF(Table3[Condition],Analysis_Sheet!D8,Table3[Age (Years)]) -> 59.84
A9: Count female patients | D9: Stroke | E9: =COUNTIF(Cleaned_Data!D:D,Cleaned_Data!D15) -> 76 | F9: =SUMIF(Table3[Condition],Analysis_Sheet!D9,Table3[Drug_Cost_GBP]) -> 97148.949 | G9: =AVERAGEIF(Table3[Condition],Analysis_Sheet!D9,Table3[Age (Years)]) -> 57.666667
A10: Count patients with Diabetes | D10: Copd | E10: =COUNTIF(Cleaned_Data!D:D,Cleaned_Data!D23) -> 76 | F10: =SUMIF(Table3[Condition],Analysis_Sheet!D10,Table3[Drug_Cost_GBP]) -> 109037.08 | G10: =AVERAGEIF(Table3[Condition],Analysis_Sheet!D10,Table3[Age (Years)]) -> 58.813084
A11: Find longest hospital stay
A12: Find shortest hospital stay
A15: Calculate total cost for Diabetes patients | B15: =SUMIF(Table3[Condition],Cleaned_Data!D6,Table3[Drug_Cost_GBP]) -> 97148.949 | D15: Count patients per hospital | F15: Average drug cost per hospital | G15: Calculate average stay per hospital
D16: Walsall Manor | E16: =COUNTIF(Table3[Hospital Name],Analysis_Sheet!D16) -> 128 | F16: =AVERAGEIF(Cleaned_Data!E:E,Analysis_Sheet!D16,Cleaned_Data!H:H) -> 988.11347 | G16: =AVERAGEIF(Table3[Hospital Name],Analysis_Sheet!D16,Table3[Length_of_Stay (Days)]) -> 11.578125
A17: Count patients with stay >10 days | B17: =COUNTIF(Table3[Length_of_Stay (Days)], "> 10") -> 735 | D17: New Cross Hospital | E17: =COUNTIF(Table3[Hospital Name],Analysis_Sheet!D17) -> 219 | F17: =AVERAGEIF(Table3[Hospital Name],Analysis_Sheet!D17,Table3[Drug_Cost_GBP]) -> 1003.247 | G17: =AVERAGEIF(Table3[Hospital Name],Analysis_Sheet!D17,Table3[Length_of_Stay (Days)]) -> 11.808219
D18: Stoke Hospital | E18: =COUNTIF(Cleaned_Data!E:E,Analysis_Sheet!D18) -> 214 | F18: =AVERAGEIF(Cleaned_Data!E:E,Analysis_Sheet!D18,Cleaned_Data!H:H) -> 1039.5824 | G18: =AVERAGEIF(Table3[Hospital Name],Analysis_Sheet!D18,Table3[Length_of_Stay (Days)]) -> 11.724299
A19: Average stay for Stroke patients | B19: =AVERAGEIFS(Table3[Length_of_Stay (Days)],Table3[Condition],Cleaned_Data!D5) -> 12.222222 | D19: Stafford Hospital | E19: =COUNTIF(Cleaned_Data!E:E,Analysis_Sheet!D19) -> 104 | F19: =AVERAGEIF(Table3[Hospital Name],Analysis_Sheet!D19,Table3[Drug_Cost_GBP]) -> 1003.6567 | G19: =AVERAGEIF(Table3[Hospital Name],Analysis_Sheet!D19,Table3[Length_of_Stay (Days)]) -> 11.673077
D20: Keele Hospital | E20: =COUNTIF(Cleaned_Data!E:E,Analysis_Sheet!D20) -> 92 | F20: =AVERAGEIF(Table3[Hospital Name],Analysis_Sheet!D20,Table3[Drug_Cost_GBP]) -> 988.02153 | G20: =AVERAGEIF(Table3[Hospital Name],Analysis_Sheet!D20,Table3[Length_of_Stay (Days)]) -> 11.782609
A21: Find patients above average cost | B21: =AVERAGE(Table3[Drug_Cost_GBP]) -> 1002.0676 | D21: Russells Hall Hospital | E21: =COUNTIF(Cleaned_Data!E:E,Analysis_Sheet!D21) -> 107 | F21: =AVERAGEIF(Table3[Hospital Name],Analysis_Sheet!D21,Table3[Drug_Cost_GBP]) -> 951.84896 | G21: =AVERAGEIF(Table3[Hospital Name],Analysis_Sheet!D21,Table3[Length_of_Stay (Days)]) -> 11.280374
A24: Count patients admitted each month
A25: Month | B25: Patient Count
A26: January 2024 | B26: =COUNTIF(Cleaned_Data!$N$2:$N$865,A26) -> 58
A27: February 2024 | B27: =COUNTIF(Cleaned_Data!$N$2:$N$865,A27) -> 62
A28: March 2024 | B28: =COUNTIF(Cleaned_Data!$N$2:$N$865,A28) -> 63
A29: April 2024 | B29: =COUNTIF(Cleaned_Data!$N$2:$N$865,A29) -> 53
A30: May 2024 | B30: =COUNTIF(Cleaned_Data!$N$2:$N$865,A30) -> 58
A31: June 2024 | B31: =COUNTIF(Cleaned_Data!$N$2:$N$865,A31) -> 62
A32: July 2024 | B32: =COUNTIF(Cleaned_Data!$N$2:$N$865,A32) -> 58
A33: August 2024 | B33: =COUNTIF(Cleaned_Data!$N$2:$N$865,A33) -> 61
A34: September 2024 | B34: =COUNTIF(Cleaned_Data!$N$2:$N$865,A34) -> 56
A35: October 2024 | B35: =COUNTIF(Cleaned_Data!$N$2:$N$865,A35) -> 58
A36: November 2024 | B36: =COUNTIF(Cleaned_Data!$N$2:$N$865,A36) -> 60
A37: December 2024 | B37: =COUNTIF(Cleaned_Data!$N$2:$N$865,A37) -> 56
A38: Unknown | B38: =COUNTIF(Cleaned_Data!$N$2:$N$865,A38) -> 159
A39: TOTAL | B39: =SUM(B26:B38) -> 864

Sheet Pivot_Table
A1: Patients per hospital | D1: Top 5 most expensive patients | G1: Gender distribution per hospital
A2: Hospital | B2: Count of Patient_ID | D2: Condition | E2: Sum of Drug_Cost_GBP | G2: Count of Patient_ID | H2: Column Labels
A3: Walsall Manor | B3: 128 | D3: P0162 | E3: 1981.64 | G3: Hospital | H3: FEMALE | I3: MALE | J3: Unknown | K3: Grand Total
A4: Stoke Hospital | B4: 214 | D4: P0397 | E4: 1994.79 | G4: Keele Hospital | H4: 39 | I4: 38 | J4: 15 | K4: 92
A5: Stafford Hospital | B5: 104 | D5: P0553 | E5: 1980.5 | G5: New Cross Hospital | H5: 84 | I5: 87 | J5: 48 | K5: 219
A6: Russells Hall Hospital | B6: 107 | D6: P0636 | E6: 1977.87 | G6: Russells Hall Hospital | H6: 39 | I6: 38 | J6: 30 | K6: 107
A7: New Cross Hospital | B7: 219 | D7: P0778 | E7: 1985.44 | G7: Stafford Hospital | H7: 46 | I7: 38 | J7: 20 | K7: 104
A8: Keele Hospital | B8: 92 | D8: Grand Total | E8: 9920.24 | G8: Stoke Hospital | H8: 88 | I8: 84 | J8: 42 | K8: 214
A9: Grand Total | B9: 864 | G9: Walsall Manor | H9: 48 | I9: 50 | J9: 30 | K9: 128
G10: Grand Total | H10: 344 | I10: 335 | J10: 185 | K10: 864
A12: Average drug cost per hospital | D12: Monthly admission trend | G12: Outcome distribution per condition
A13: Hospital | B13: Average of Drug_Cost_GBP | D13: Hospital | E13: Count of Patient_ID | G13: Count of Patient_ID | H13: Column Labels
A14: Keele Hospital | B14: 988.02153 | D14: April 2024 | E14: 53 | G14: Condition | H14: Deceased | I14: Ongoing | J14: Recovered | K14: Referred | L14: Unknown | M14: Grand Total
A15: New Cross Hospital | B15: 1003.247 | D15: August 2024 | E15: 61 | G15: Asthma | H15: 21 | I15: 12 | J15: 27 | K15: 18 | L15: 22 | M15: 100
A16: Russells Hall Hospital | B16: 951.84896 | D16: December 2024 | E16: 56 | G16: Copd | H16: 24 | I16: 23 | J16: 19 | K16: 19 | L16: 22 | M16: 107
A17: Stafford Hospital | B17: 1003.6567 | D17: February 2024 | E17: 62 | G17: Diabetes | H17: 37 | I17: 38 | J17: 35 | K17: 38 | L17: 28 | M17: 176
A18: Stoke Hospital | B18: 1039.5824 | D18: January 2024 | E18: 58 | G18: Heart Disease | H18: 11 | I18: 15 | J18: 17 | K18: 17 | L18: 16 | M18: 76
A19: Walsall Manor | B19: 988.11347 | D19: July 2024 | E19: 58 | G19: Hypertension | H19: 21 | I19: 20 | J19: 26 | K19: 17 | L19: 15 | M19: 99
A20: Grand Total | B20: 1002.0676 | D20: June 2024 | E20: 62 | G20: Kidney Disease | H20: 14 | I20: 16 | J20: 28 | K20: 13 | L20: 23 | M20: 94
D21: March 2024 | E21: 63 | G21: Stroke | H21: 16 | I21: 24 | J21: 13 | K21: 27 | L21: 19 | M21: 99
D22: May 2024 | E22: 58 | G22: Unknown | H22: 14 | I22: 35 | J22: 20 | K22: 20 | L22: 24 | M22: 113
A23: Average stay per condition | D23: November 2024 | E23: 60 | G23: Grand Total | H23: 158 | I23: 183 | J23: 185 | K23: 169 | L23: 169 | M23: 864
A24: Condition | B24: Average of Length_of_Stay (Days) | D24: October 2024 | E24: 58
A25: Asthma | B25: 11.73 | D25: September 2024 | E25: 56
A26: Copd | B26: 11.523364 | D26: Unknown | E26: 159 | G26: Total cost per condition
A27: Diabetes | B27: 11.5625 | D27: Grand Total | E27: 864 | G27: Condition | H27: Sum of Drug_Cost_GBP
A28: Heart Disease | B28: 11.605263 | G28: Asthma | H28: 102231.27
A29: Hypertension | B29: 11.535354 | G29: Copd | H29: 109037.08
A30: Kidney Disease | B30: 11.946809 | D30: Total cost per hospital | G30: Diabetes | H30: 179621.85
A31: Stroke | B31: 12.222222 | D31: Hospital | E31: Sum of Drug_Cost_GBP | G31: Heart Disease | H31: 75629.638
A32: Unknown | B32: 11.362832 | D32: Keele Hospital | E32: 90897.981 | G32: Hypertension | H32: 98783.826
A33: Grand Total | B33: 11.668981 | D33: New Cross Hospital | E33: 219711.08 | G33: Kidney Disease | H33: 91073.646
D34: Russells Hall Hospital | E34: 101847.84 | G34: Stroke | H34: 97148.949
D35: Stafford Hospital | E35: 104380.3 | G35: Unknown | H35: 112260.11
D36: Stoke Hospital | E36: 222470.64 | G36: Grand Total | H36: 865786.36
D37: Walsall Manor | E37: 126478.52
D38: Grand Total | E38: 865786.36

Sheet KPI
A3: Count of Patient_ID
A4: 864
A7: Sum of Drug_Cost_GBP
A8: 865786.36
A11: Average of Length_of_Stay (Days)
A12: 11.668981
A15: Average of Age (Years)
A16: 57.15625

Sheet Dashboard
A1: Dashboard
A3: KPI
A4: Total Patients | C4: Total Drug Cost | E4: Avg Length of Stay | G4: Avg Age
A5: =KPI!A4 -> 864 | C5: =KPI!A8 -> 865786.36 | E5: =KPI!A12 -> 11.668981 | G5: =KPI!A16 -> 57.15625
